Workbook
Name FromArray_1: _xlfn.ANCHORARRAY(Mardi!$A$2)

Sheet Mardi
A1: Nom | B1: Prénom | C1: Tâche | D1: Début | E1: Fin
A2: =[1]Personnes!A2 -> Bouvet | B2: =[1]Personnes!B2 -> Agathe
A3: =[1]Personnes!A3 -> Bulka | B3: =[1]Personnes!B3 -> Alegria Lily
A4: =[1]Personnes!A4 -> Bastian | B4: =[1]Personnes!B4 -> Alexandra
A5: =[1]Personnes!A5 -> L'Horset | B5: =[1]Personnes!B5 -> Alice
A6: =[1]Personnes!A6 -> Ledru | B6: =[1]Personnes!B6 -> Ana-Lou
A7: =[1]Personnes!A7 -> Pero | B7: =[1]Personnes!B7 -> Andy
A8: =[1]Personnes!A8 -> Mallet | B8: =[1]Personnes!B8 -> Anna
A9: =[1]Personnes!A9 -> Malric | B9: =[1]Personnes!B9 -> Annouk
A10: =[1]Personnes!A10 -> Noël | B10: =[1]Personnes!B10 -> Antonin
A11: =[1]Personnes!A11 -> Tessier | B11: =[1]Personnes!B11 -> Arsène
A12: =[1]Personnes!A12 -> Uldry | B12: =[1]Personnes!B12 -> Arthur
A13: =[1]Personnes!A13 -> Marchand | B13: =[1]Personnes!B13 -> Athénaé
... A37: =[1]Personnes!A37 -> Chambaz | B37: =[1]Personnes!B37 -> Maëlle
A38: =[1]Personnes!A38 -> Felix | B38: =[1]Personnes!B38 -> Marius | C38: Tech Phusis | D38: 0.75 | E38: 0.8125
A39: =[1]Personnes!A39 -> Ledru | B39: =[1]Personnes!B39 -> Marot
A40: =[1]Personnes!A40 -> Cuinet | B40: =[1]Personnes!B40 -> Mathis
A41: =[1]Personnes!A41 -> Gavin | B41: =[1]Personnes!B41 -> Matteo
A42: =[1]Personnes!A42 -> Debray | B42: =[1]Personnes!B42 -> Maxime | C42: Tech Jacquard | D42: 0.84375 | E42: 0.9375
A43: =[1]Personnes!A43 -> Corbelli | B43: =[1]Personnes!B43 -> Maya
A44: =[1]Personnes!A44 -> Pasche | B44: =[1]Personnes!B44 -> Mickaël
A45: =[1]Personnes!A45 -> Ménard | B45: =[1]Personnes!B45 -> Mireille
A46: =[1]Personnes!A46 -> Fargues | B46: =[1]Personnes!B46 -> Morgana | C46: Tech PCGB | D46: 0.8125 | E46: 0.85416667
A47: =[1]Personnes!A47 -> Scyboz (Lambelet) | B47: =[1]Personnes!B47 -> Morgane
A48: =[1]Personnes!A48 -> Koux | B48: =[1]Personnes!B48 -> Nathalia
A49: =[1]Personnes!A49 -> Cherpillod | B49: =[1]Personnes!B49 -> Noah
A50: =[1]Personnes!A50 -> Chambaz | B50: =[1]Personnes!B50 -> Patrick
A51: =[1]Personnes!A51 -> Assaoui | B51: =[1]Personnes!B51 -> Rama
A52: =[1]Personnes!A52 -> Lacroze | B52: =[1]Personnes!B52 -> Raphaël | C52: Tech T'es rien… | D52: 0.70833333 | E52: 0.77083333
A53: =[1]Personnes!A53 -> Neidhart | B53: =[1]Personnes!B53 -> Raphaëlle
A54: =[1]Personnes!A54 -> Lanni | B54: =[1]Personnes!B54 -> Roxanne
A55: =[1]Personnes!A55 -> Schiesser | B55: =[1]Personnes!B55 -> Sébastien
A56: =[1]Personnes!A56 -> Lambelet | B56: =[1]Personnes!B56 -> Simon
A57: =[1]Personnes!A57 -> Cyprien | B57: =[1]Personnes!B57 -> Theo
A58: =[1]Personnes!A58 -> Clerici | B58: =[1]Personnes!B58 -> Thibault
A59: =[1]Personnes!A59 -> Lagier | B59: =[1]Personnes!B59 -> Tician
A60: =[1]Personnes!A60 -> Ménétrey | B60: =[1]Personnes!B60 -> Titouan
A61: =[1]Personnes!A61 -> Clerici | B61: =[1]Personnes!B61 -> Tristan
A62: =[1]Personnes!A62 -> Bally | B62: =[1]Personnes!B62 -> Yann
A63: =[1]Personnes!A63 -> Ménétrey | B63: =[1]Personnes!B63 -> Ysatis
...

Sheet Mercredi
A1: Nom | B1: Prénom | C1: Tâche | D1: Début | E1: Fin
A2: =[1]Personnes!A2 -> Bouvet | B2: =[1]Personnes!B2 -> Agathe
A3: =[1]Personnes!A3 -> Bulka | B3: =[1]Personnes!B3 -> Alegria Lily
A4: =[1]Personnes!A4 -> Bastian | B4: =[1]Personnes!B4 -> Alexandra
A5: =[1]Personnes!A5 -> L'Horset | B5: =[1]Personnes!B5 -> Alice
A6: =[1]Personnes!A6 -> Ledru | B6: =[1]Personnes!B6 -> Ana-Lou
A7: =[1]Personnes!A7 -> Pero | B7: =[1]Personnes!B7 -> Andy
A8: =[1]Personnes!A8 -> Mallet | B8: =[1]Personnes!B8 -> Anna
A9: =[1]Personnes!A9 -> Malric | B9: =[1]Personnes!B9 -> Annouk
A10: =[1]Personnes!A10 -> Noël | B10: =[1]Personnes!B10 -> Antonin
A11: =[1]Personnes!A11 -> Tessier | B11: =[1]Personnes!B11 -> Arsène
A12: =[1]Personnes!A12 -> Uldry | B12: =[1]Personnes!B12 -> Arthur
A13: =[1]Personnes!A13 -> Marchand | B13: =[1]Personnes!B13 -> Athénaé
... A38: =[1]Personnes!A38 -> Felix | B38: =[1]Personnes!B38 -> Marius
A39: =[1]Personnes!A39 -> Ledru | B39: =[1]Personnes!B39 -> Marot | C39: Tech PCGB | D39: 0.79166667 | E39: 0.875
A40: =[1]Personnes!A40 -> Cuinet | B40: =[1]Personnes!B40 -> Mathis
A41: =[1]Personnes!A41 -> Gavin | B41: =[1]Personnes!B41 -> Matteo
A42: =[1]Personnes!A42 -> Debray | B42: =[1]Personnes!B42 -> Maxime
A43: =[1]Personnes!A43 -> Corbelli | B43: =[1]Personnes!B43 -> Maya | C43: Tech Muchmuche | D43: 0.75 | E43: 0.83333333
A44: =[1]Personnes!A44 -> Pasche | B44: =[1]Personnes!B44 -> Mickaël
A45: =[1]Personnes!A45 -> Ménard | B45: =[1]Personnes!B45 -> Mireille
A46: =[1]Personnes!A46 -> Fargues | B46: =[1]Personnes!B46 -> Morgana
A47: =[1]Personnes!A47 -> Scyboz (Lambelet) | B47: =[1]Personnes!B47 -> Morgane
A48: =[1]Personnes!A48 -> Koux | B48: =[1]Personnes!B48 -> Nathalia
A49: =[1]Personnes!A49 -> Cherpillod | B49: =[1]Personnes!B49 -> Noah
A50: =[1]Personnes!A50 -> Chambaz | B50: =[1]Personnes!B50 -> Patrick
A51: =[1]Personnes!A51 -> Assaoui | B51: =[1]Personnes!B51 -> Rama
A52: =[1]Personnes!A52 -> Lacroze | B52: =[1]Personnes!B52 -> Raphaël | C52: Tech T'es rien… | D52: 0.70833333 | E52: 0.79166667
A53: =[1]Personnes!A53 -> Neidhart | B53: =[1]Personnes!B53 -> Raphaëlle
A54: =[1]Personnes!A54 -> Lanni | B54: =[1]Personnes!B54 -> Roxanne
A55: =[1]Personnes!A55 -> Schiesser | B55: =[1]Personnes!B55 -> Sébastien
A56: =[1]Personnes!A56 -> Lambelet | B56: =[1]Personnes!B56 -> Simon
A57: =[1]Personnes!A57 -> Cyprien | B57: =[1]Personnes!B57 -> Theo
A58: =[1]Personnes!A58 -> Clerici | B58: =[1]Personnes!B58 -> Thibault
A59: =[1]Personnes!A59 -> Lagier | B59: =[1]Personnes!B59 -> Tician
A60: =[1]Personnes!A60 -> Ménétrey | B60: =[1]Personnes!B60 -> Titouan
A61: =[1]Personnes!A61 -> Clerici | B61: =[1]Personnes!B61 -> Tristan
A62: =[1]Personnes!A62 -> Bally | B62: =[1]Personnes!B62 -> Yann
A63: =[1]Personnes!A63 -> Ménétrey | B63: =[1]Personnes!B63 -> Ysatis
A64: =[1]Personnes!A64 -> Scyboz (Lambelet) | B64: =[1]Personnes!B64 -> Alex
...

Sheet Jeudi
A1: Nom | B1: Prénom | C1: Tâche | D1: Début | E1: Fin
A2: =[1]Personnes!A2 -> Bouvet | B2: =[1]Personnes!B2 -> Agathe
A3: =[1]Personnes!A3 -> Bulka | B3: =[1]Personnes!B3 -> Alegria Lily
A4: =[1]Personnes!A4 -> Bastian | B4: =[1]Personnes!B4 -> Alexandra
A5: =[1]Personnes!A5 -> L'Horset | B5: =[1]Personnes!B5 -> Alice
A6: =[1]Personnes!A6 -> Ledru | B6: =[1]Personnes!B6 -> Ana-Lou
A7: =[1]Personnes!A7 -> Pero | B7: =[1]Personnes!B7 -> Andy
A8: =[1]Personnes!A8 -> Mallet | B8: =[1]Personnes!B8 -> Anna
A9: =[1]Personnes!A9 -> Malric | B9: =[1]Personnes!B9 -> Annouk
A10: =[1]Personnes!A10 -> Noël | B10: =[1]Personnes!B10 -> Antonin
A11: =[1]Personnes!A11 -> Tessier | B11: =[1]Personnes!B11 -> Arsène
A12: =[1]Personnes!A12 -> Uldry | B12: =[1]Personnes!B12 -> Arthur
A13: =[1]Personnes!A13 -> Marchand | B13: =[1]Personnes!B13 -> Athénaé
... A38: =[1]Personnes!A38 -> Felix | B38: =[1]Personnes!B38 -> Marius
A39: =[1]Personnes!A39 -> Ledru | B39: =[1]Personnes!B39 -> Marot | C39: Tech PCGB | D39: 0.79166667 | E39: 0.875
A40: =[1]Personnes!A40 -> Cuinet | B40: =[1]Personnes!B40 -> Mathis
A41: =[1]Personnes!A41 -> Gavin | B41: =[1]Personnes!B41 -> Matteo
A42: =[1]Personnes!A42 -> Debray | B42: =[1]Personnes!B42 -> Maxime
A43: =[1]Personnes!A43 -> Corbelli | B43: =[1]Personnes!B43 -> Maya | C43: Tech Muchmuche | D43: 0.75 | E43: 0.83333333
A44: =[1]Personnes!A44 -> Pasche | B44: =[1]Personnes!B44 -> Mickaël
A45: =[1]Personnes!A45 -> Ménard | B45: =[1]Personnes!B45 -> Mireille
A46: =[1]Personnes!A46 -> Fargues | B46: =[1]Personnes!B46 -> Morgana
A47: =[1]Personnes!A47 -> Scyboz (Lambelet) | B47: =[1]Personnes!B47 -> Morgane
A48: =[1]Personnes!A48 -> Koux | B48: =[1]Personnes!B48 -> Nathalia
A49: =[1]Personnes!A49 -> Cherpillod | B49: =[1]Personnes!B49 -> Noah
A50: =[1]Personnes!A50 -> Chambaz | B50: =[1]Personnes!B50 -> Patrick
A51: =[1]Personnes!A51 -> Assaoui | B51: =[1]Personnes!B51 -> Rama
A52: =[1]Personnes!A52 -> Lacroze | B52: =[1]Personnes!B52 -> Raphaël | C52: Tech T'es rien… | D52: 0.70833333 | E52: 0.79166667
A53: =[1]Personnes!A53 -> Neidhart | B53: =[1]Personnes!B53 -> Raphaëlle
A54: =[1]Personnes!A54 -> Lanni | B54: =[1]Personnes!B54 -> Roxanne
A55: =[1]Personnes!A55 -> Schiesser | B55: =[1]Personnes!B55 -> Sébastien
A56: =[1]Personnes!A56 -> Lambelet | B56: =[1]Personnes!B56 -> Simon
A57: =[1]Personnes!A57 -> Cyprien | B57: =[1]Personnes!B57 -> Theo
A58: =[1]Personnes!A58 -> Clerici | B58: =[1]Personnes!B58 -> Thibault
A59: =[1]Personnes!A59 -> Lagier | B59: =[1]Personnes!B59 -> Tician
A60: =[1]Personnes!A60 -> Ménétrey | B60: =[1]Personnes!B60 -> Titouan
A61: =[1]Personnes!A61 -> Clerici | B61: =[1]Personnes!B61 -> Tristan
A62: =[1]Personnes!A62 -> Bally | B62: =[1]Personnes!B62 -> Yann
A63: =[1]Personnes!A63 -> Ménétrey | B63: =[1]Personnes!B63 -> Ysatis
A64: =[1]Personnes!A64 -> Scyboz (Lambelet) | B64: =[1]Personnes!B64 -> Alex

Sheet Vendredi
A1: Nom | B1: Prénom | C1: Tâche | D1: Début | E1: Fin
A2: =[1]Personnes!A2 -> Bouvet | B2: =[1]Personnes!B2 -> Agathe
A3: =[1]Personnes!A3 -> Bulka | B3: =[1]Personnes!B3 -> Alegria Lily
A4: =[1]Personnes!A4 -> Bastian | B4: =[1]Personnes!B4 -> Alexandra
A5: =[1]Personnes!A5 -> L'Horset | B5: =[1]Personnes!B5 -> Alice
A6: =[1]Personnes!A6 -> Ledru | B6: =[1]Personnes!B6 -> Ana-Lou
A7: =[1]Personnes!A7 -> Pero | B7: =[1]Personnes!B7 -> Andy
A8: =[1]Personnes!A8 -> Mallet | B8: =[1]Personnes!B8 -> Anna
A9: =[1]Personnes!A9 -> Malric | B9: =[1]Personnes!B9 -> Annouk
A10: =[1]Personnes!A10 -> Noël | B10: =[1]Personnes!B10 -> Antonin
A11: =[1]Personnes!A11 -> Tessier | B11: =[1]Personnes!B11 -> Arsène
A12: =[1]Personnes!A12 -> Uldry | B12: =[1]Personnes!B12 -> Arthur
A13: =[1]Personnes!A13 -> Marchand | B13: =[1]Personnes!B13 -> Athénaé
... A38: =[1]Personnes!A38 -> Felix | B38: =[1]Personnes!B38 -> Marius
A39: =[1]Personnes!A39 -> Ledru | B39: =[1]Personnes!B39 -> Marot | C39: Tech PCGB | D39: 0.79166667 | E39: 0.875
A40: =[1]Personnes!A40 -> Cuinet | B40: =[1]Personnes!B40 -> Mathis
A41: =[1]Personnes!A41 -> Gavin | B41: =[1]Personnes!B41 -> Matteo
A42: =[1]Personnes!A42 -> Debray | B42: =[1]Personnes!B42 -> Maxime
A43: =[1]Personnes!A43 -> Corbelli | B43: =[1]Personnes!B43 -> Maya | C43: Tech Muchmuche | D43: 0.75 | E43: 0.83333333
A44: =[1]Personnes!A44 -> Pasche | B44: =[1]Personnes!B44 -> Mickaël
A45: =[1]Personnes!A45 -> Ménard | B45: =[1]Personnes!B45 -> Mireille
A46: =[1]Personnes!A46 -> Fargues | B46: =[1]Personnes!B46 -> Morgana
A47: =[1]Personnes!A47 -> Scyboz (Lambelet) | B47: =[1]Personnes!B47 -> Morgane
A48: =[1]Personnes!A48 -> Koux | B48: =[1]Personnes!B48 -> Nathalia
A49: =[1]Personnes!A49 -> Cherpillod | B49: =[1]Personnes!B49 -> Noah
A50: =[1]Personnes!A50 -> Chambaz | B50: =[1]Personnes!B50 -> Patrick
A51: =[1]Personnes!A51 -> Assaoui | B51: =[1]Personnes!B51 -> Rama
A52: =[1]Personnes!A52 -> Lacroze | B52: =[1]Personnes!B52 -> Raphaël | C52: Tech T'es rien… | D52: 0.70833333 | E52: 0.79166667
A53: =[1]Personnes!A53 -> Neidhart | B53: =[1]Personnes!B53 -> Raphaëlle
A54: =[1]Personnes!A54 -> Lanni | B54: =[1]Personnes!B54 -> Roxanne
A55: =[1]Personnes!A55 -> Schiesser | B55: =[1]Personnes!B55 -> Sébastien
A56: =[1]Personnes!A56 -> Lambelet | B56: =[1]Personnes!B56 -> Simon
A57: =[1]Personnes!A57 -> Cyprien | B57: =[1]Personnes!B57 -> Theo
A58: =[1]Personnes!A58 -> Clerici | B58: =[1]Personnes!B58 -> Thibault
A59: =[1]Personnes!A59 -> Lagier | B59: =[1]Personnes!B59 -> Tician
A60: =[1]Personnes!A60 -> Ménétrey | B60: =[1]Personnes!B60 -> Titouan
A61: =[1]Personnes!A61 -> Clerici | B61: =[1]Personnes!B61 -> Tristan
A62: =[1]Personnes!A62 -> Bally | B62: =[1]Personnes!B62 -> Yann
A63: =[1]Personnes!A63 -> Ménétrey | B63: =[1]Personnes!B63 -> Ysatis
A64: =[1]Personnes!A64 -> Scyboz (Lambelet) | B64: =[1]Personnes!B64 -> Alex

Sheet Samedi
A1: Nom | B1: Prénom | C1: Tâche | D1: Début | E1: Fin
A2: =[1]Personnes!A2 -> Bouvet | B2: =[1]Personnes!B2 -> Agathe
A3: =[1]Personnes!A3 -> Bulka | B3: =[1]Personnes!B3 -> Alegria Lily
A4: =[1]Personnes!A4 -> Bastian | B4: =[1]Personnes!B4 -> Alexandra
A5: =[1]Personnes!A5 -> L'Horset | B5: =[1]Personnes!B5 -> Alice
A6: =[1]Personnes!A6 -> Ledru | B6: =[1]Personnes!B6 -> Ana-Lou
A7: =[1]Personnes!A7 -> Pero | B7: =[1]Personnes!B7 -> Andy
A8: =[1]Personnes!A8 -> Mallet | B8: =[1]Personnes!B8 -> Anna
A9: =[1]Personnes!A9 -> Malric | B9: =[1]Personnes!B9 -> Annouk
A10: =[1]Personnes!A10 -> Noël | B10: =[1]Personnes!B10 -> Antonin
A11: =[1]Personnes!A11 -> Tessier | B11: =[1]Personnes!B11 -> Arsène
A12: =[1]Personnes!A12 -> Uldry | B12: =[1]Personnes!B12 -> Arthur
A13: =[1]Personnes!A13 -> Marchand | B13: =[1]Personnes!B13 -> Athénaé
... A38: =[1]Personnes!A38 -> Felix | B38: =[1]Personnes!B38 -> Marius
A39: =[1]Personnes!A39 -> Ledru | B39: =[1]Personnes!B39 -> Marot | C39: Tech PCGB | D39: 0.79166667 | E39: 0.875
A40: =[1]Personnes!A40 -> Cuinet | B40: =[1]Personnes!B40 -> Mathis
A41: =[1]Personnes!A41 -> Gavin | B41: =[1]Personnes!B41 -> Matteo
A42: =[1]Personnes!A42 -> Debray | B42: =[1]Personnes!B42 -> Maxime
A43: =[1]Personnes!A43 -> Corbelli | B43: =[1]Personnes!B43 -> Maya | C43: Tech Muchmuche | D43: 0.75 | E43: 0.83333333
A44: =[1]Personnes!A44 -> Pasche | B44: =[1]Personnes!B44 -> Mickaël
A45: =[1]Personnes!A45 -> Ménard | B45: =[1]Personnes!B45 -> Mireille
A46: =[1]Personnes!A46 -> Fargues | B46: =[1]Personnes!B46 -> Morgana
A47: =[1]Personnes!A47 -> Scyboz (Lambelet) | B47: =[1]Personnes!B47 -> Morgane
A48: =[1]Personnes!A48 -> Koux | B48: =[1]Personnes!B48 -> Nathalia
A49: =[1]Personnes!A49 -> Cherpillod | B49: =[1]Personnes!B49 -> Noah
A50: =[1]Personnes!A50 -> Chambaz | B50: =[1]Personnes!B50 -> Patrick
A51: =[1]Personnes!A51 -> Assaoui | B51: =[1]Personnes!B51 -> Rama
A52: =[1]Personnes!A52 -> Lacroze | B52: =[1]Personnes!B52 -> Raphaël | C52: Tech T'es rien… | D52: 0.70833333 | E52: 0.79166667
A53: =[1]Personnes!A53 -> Neidhart | B53: =[1]Personnes!B53 -> Raphaëlle
A54: =[1]Personnes!A54 -> Lanni | B54: =[1]Personnes!B54 -> Roxanne
A55: =[1]Personnes!A55 -> Schiesser | B55: =[1]Personnes!B55 -> Sébastien
A56: =[1]Personnes!A56 -> Lambelet | B56: =[1]Personnes!B56 -> Simon
A57: =[1]Personnes!A57 -> Cyprien | B57: =[1]Personnes!B57 -> Theo
A58: =[1]Personnes!A58 -> Clerici | B58: =[1]Personnes!B58 -> Thibault
A59: =[1]Personnes!A59 -> Lagier | B59: =[1]Personnes!B59 -> Tician
A60: =[1]Personnes!A60 -> Ménétrey | B60: =[1]Personnes!B60 -> Titouan
A61: =[1]Personnes!A61 -> Clerici | B61: =[1]Personnes!B61 -> Tristan
A62: =[1]Personnes!A62 -> Bally | B62: =[1]Personnes!B62 -> Yann
A63: =[1]Personnes!A63 -> Ménétrey | B63: =[1]Personnes!B63 -> Ysatis
A64: =[1]Personnes!A64 -> Scyboz (Lambelet) | B64: =[1]Personnes!B64 -> Alex

Sheet Dimanche
A1: Nom | B1: Prénom | C1: Tâche | D1: Début | E1: Fin
A2: =[1]Personnes!A2 -> Bouvet | B2: =[1]Personnes!B2 -> Agathe
A3: =[1]Personnes!A3 -> Bulka | B3: =[1]Personnes!B3 -> Alegria Lily
A4: =[1]Personnes!A4 -> Bastian | B4: =[1]Personnes!B4 -> Alexandra
A5: =[1]Personnes!A5 -> L'Horset | B5: =[1]Personnes!B5 -> Alice
A6: =[1]Personnes!A6 -> Ledru | B6: =[1]Personnes!B6 -> Ana-Lou
A7: =[1]Personnes!A7 -> Pero | B7: =[1]Personnes!B7 -> Andy
A8: =[1]Personnes!A8 -> Mallet | B8: =[1]Personnes!B8 -> Anna
A9: =[1]Personnes!A9 -> Malric | B9: =[1]Personnes!B9 -> Annouk
A10: =[1]Personnes!A10 -> Noël | B10: =[1]Personnes!B10 -> Antonin
A11: =[1]Personnes!A11 -> Tessier | B11: =[1]Personnes!B11 -> Arsène
A12: =[1]Personnes!A12 -> Uldry | B12: =[1]Personnes!B12 -> Arthur
A13: =[1]Personnes!A13 -> Marchand | B13: =[1]Personnes!B13 -> Athénaé
... A38: =[1]Personnes!A38 -> Felix | B38: =[1]Personnes!B38 -> Marius
A39: =[1]Personnes!A39 -> Ledru | B39: =[1]Personnes!B39 -> Marot | C39: Tech PCGB | D39: 0.79166667 | E39: 0.875
A40: =[1]Personnes!A40 -> Cuinet | B40: =[1]Personnes!B40 -> Mathis
A41: =[1]Personnes!A41 -> Gavin | B41: =[1]Personnes!B41 -> Matteo
A42: =[1]Personnes!A42 -> Debray | B42: =[1]Personnes!B42 -> Maxime
A43: =[1]Personnes!A43 -> Corbelli | B43: =[1]Personnes!B43 -> Maya | C43: Tech Muchmuche | D43: 0.75 | E43: 0.83333333
A44: =[1]Personnes!A44 -> Pasche | B44: =[1]Personnes!B44 -> Mickaël
A45: =[1]Personnes!A45 -> Ménard | B45: =[1]Personnes!B45 -> Mireille
A46: =[1]Personnes!A46 -> Fargues | B46: =[1]Personnes!B46 -> Morgana
A47: =[1]Personnes!A47 -> Scyboz (Lambelet) | B47: =[1]Personnes!B47 -> Morgane
A48: =[1]Personnes!A48 -> Koux | B48: =[1]Personnes!B48 -> Nathalia
A49: =[1]Personnes!A49 -> Cherpillod | B49: =[1]Personnes!B49 -> Noah
A50: =[1]Personnes!A50 -> Chambaz | B50: =[1]Personnes!B50 -> Patrick
A51: =[1]Personnes!A51 -> Assaoui | B51: =[1]Personnes!B51 -> Rama
A52: =[1]Personnes!A52 -> Lacroze | B52: =[1]Personnes!B52 -> Raphaël | C52: Tech T'es rien… | D52: 0.70833333 | E52: 0.79166667
A53: =[1]Personnes!A53 -> Neidhart | B53: =[1]Personnes!B53 -> Raphaëlle
A54: =[1]Personnes!A54 -> Lanni | B54: =[1]Personnes!B54 -> Roxanne
A55: =[1]Personnes!A55 -> Schiesser | B55: =[1]Personnes!B55 -> Sébastien
A56: =[1]Personnes!A56 -> Lambelet | B56: =[1]Personnes!B56 -> Simon
A57: =[1]Personnes!A57 -> Cyprien | B57: =[1]Personnes!B57 -> Theo
A58: =[1]Personnes!A58 -> Clerici | B58: =[1]Personnes!B58 -> Thibault
A59: =[1]Personnes!A59 -> Lagier | B59: =[1]Personnes!B59 -> Tician
A60: =[1]Personnes!A60 -> Ménétrey | B60: =[1]Personnes!B60 -> Titouan
A61: =[1]Personnes!A61 -> Clerici | B61: =[1]Personnes!B61 -> Tristan
A62: =[1]Personnes!A62 -> Bally | B62: =[1]Personnes!B62 -> Yann
A63: =[1]Personnes!A63 -> Ménétrey | B63: =[1]Personnes!B63 -> Ysatis
A64: =[1]Personnes!A64 -> Scyboz (Lambelet) | B64: =[1]Personnes!B64 -> Alex

Sheet Taches
A1: =[2]Tâches!$A1 -> Tâches communes
A2: =[2]Tâches!$A2 -> Abeille Entrée
A3: =[2]Tâches!$A3 -> Abeille Ruche
A4: =[2]Tâches!$A4 -> Ailes
A5: =[2]Tâches!$A5 -> Bar loges
A6: =[2]Tâches!$A6 -> Bar public
A7: =[2]Tâches!$A7 -> Déambule Gerry
A8: =[2]Tâches!$A8 -> Déambule Colbok
A9: =[2]Tâches!$A9 -> Déambule Goulus
A10: Stageman
A11: =[2]Tâches!$A10 -> Déambule Volkanik
A12: =[2]Tâches!$A11 -> Déambule Spoutnik
A13: =[2]Tâches!$A12 -> Déambule FBI
A14: =[2]Tâches!$A13 -> Tech PCGB
A15: =[2]Tâches!$A14 -> Tech Jacquard
A16: =[2]Tâches!$A15 -> Tech Phusis
A17: =[2]Tâches!$A16 -> Tech T'es rien
A18: =[2]Tâches!$A17 -> 0
A19: =[2]Tâches!$A18 -> 0
A20: =[2]Tâches!$A19 -> 0
